Workbook

Sheet Résumé
B2: Heart & Soul — Checklist de test
B3: Généré à partir de docs/heart_and_soul/quick_test_checklist.md — à dérouler sur une partie neuve, jamais une sauvegarde continuée.
B5: Total des points | C5: OK | D5: KO | E5: Non testé | F5: % complété
B6: =COUNTA(Checklist!A4:A101) | C6: =COUNTIF(Checklist!E4:E101,"OK") | D6: =COUNTIF(Checklist!E4:E101,"KO") | E6: =COUNTIF(Checklist!E4:E101,"Non testé") | F6: =IFERROR(C6/B6,0)
B8: Répartition par section
B9: Section | C9: Points | D9: OK | E9: KO | F9: Non testé
B10: 1. Lancement / création de personnage | C10: =COUNTIF(Checklist!B4:B101,B10) | D10: =COUNTIFS(Checklist!B4:B101,B10,Checklist!E4:E101,"OK") | E10: =COUNTIFS(Checklist!B4:B101,B10,Checklist!E4:E101,"KO") | F10: =COUNTIFS(Checklist!B4:B101,B10,Checklist!E4:E101,"Non testé")
B11: 2. Choix du type et de l'équipe | C11: =COUNTIF(Checklist!B4:B101,B11) | D11: =COUNTIFS(Checklist!B4:B101,B11,Checklist!E4:E101,"OK") | E11: =COUNTIFS(Checklist!B4:B101,B11,Checklist!E4:E101,"KO") | F11: =COUNTIFS(Checklist!B4:B101,B11,Checklist!E4:E101,"Non testé")
B12: 3. Attaque de Cinnabar (Acte I) | C12: =COUNTIF(Checklist!B4:B101,B12) | D12: =COUNTIFS(Checklist!B4:B101,B12,Checklist!E4:E101,"OK") | E12: =COUNTIFS(Checklist!B4:B101,B12,Checklist!E4:E101,"KO") | F12: =COUNTIFS(Checklist!B4:B101,B12,Checklist!E4:E101,"Non testé")
B13: 4. Route 1 | C13: =COUNTIF(Checklist!B4:B101,B13) | D13: =COUNTIFS(Checklist!B4:B101,B13,Checklist!E4:E101,"OK") | E13: =COUNTIFS(Checklist!B4:B101,B13,Checklist!E4:E101,"KO") | F13: =COUNTIFS(Checklist!B4:B101,B13,Checklist!E4:E101,"Non testé")
B14: 5. Viridian (Argenta) | C14: =COUNTIF(Checklist!B4:B101,B14) | D14: =COUNTIFS(Checklist!B4:B101,B14,Checklist!E4:E101,"OK") | E14: =COUNTIFS(Checklist!B4:B101,B14,Checklist!E4:E101,"KO") | F14: =COUNTIFS(Checklist!B4:B101,B14,Checklist!E4:E101,"Non testé")
B15: 6. Forêt de Jade (Viridian Forest) | C15: =COUNTIF(Checklist!B4:B101,B15) | D15: =COUNTIFS(Checklist!B4:B101,B15,Checklist!E4:E101,"OK") | E15: =COUNTIFS(Checklist!B4:B101,B15,Checklist!E4:E101,"KO") | F15: =COUNTIFS(Checklist!B4:B101,B15,Checklist!E4:E101,"Non testé")
B16: 7. Argenta → Jadielle → Azuria (route et niveaux) | C16: =COUNTIF(Checklist!B4:B101,B16) | D16: =COUNTIFS(Checklist!B4:B101,B16,Checklist!E4:E101,"OK") | E16: =COUNTIFS(Checklist!B4:B101,B16,Checklist!E4:E101,"KO") | F16: =COUNTIFS(Checklist!B4:B101,B16,Checklist!E4:E101,"Non testé")
B17: 8. Arène de Pierre (Jadielle) | C17: =COUNTIF(Checklist!B4:B101,B17) | D17: =COUNTIFS(Checklist!B4:B101,B17,Checklist!E4:E101,"OK") | E17: =COUNTIFS(Checklist!B4:B101,B17,Checklist!E4:E101,"KO") | F17: =COUNTIFS(Checklist!B4:B101,B17,Checklist!E4:E101,"Non testé")
B18: 9. Azuria | C18: =COUNTIF(Checklist!B4:B101,B18) | D18: =COUNTIFS(Checklist!B4:B101,B18,Checklist!E4:E101,"OK") | E18: =COUNTIFS(Checklist!B4:B101,B18,Checklist!E4:E101,"KO") | F18: =COUNTIFS(Checklist!B4:B101,B18,Checklist!E4:E101,"Non testé")
B19: 10. Route vers Carmin-sur-Mer (Vermilion) | C19: =COUNTIF(Checklist!B4:B101,B19) | D19: =COUNTIFS(Checklist!B4:B101,B19,Checklist!E4:E101,"OK") | E19: =COUNTIFS(Checklist!B4:B101,B19,Checklist!E4:E101,"KO") | F19: =COUNTIFS(Checklist!B4:B101,B19,Checklist!E4:E101,"Non testé")
B20: 11. Arène de Major Bob (Carmin-sur-Mer, 4e arène) | C20: =COUNTIF(Checklist!B4:B101,B20) | D20: =COUNTIFS(Checklist!B4:B101,B20,Checklist!E4:E101,"OK") | E20: =COUNTIFS(Checklist!B4:B101,B20,Checklist!E4:E101,"KO") | F20: =COUNTIFS(Checklist!B4:B101,B20,Checklist!E4:E101,"Non testé")
B21: 12. Portes de Cinnabar (Arène/Manoir/Labo) — build séparé | C21: =COUNTIF(Checklist!B4:B101,B21) | D21: =COUNTIFS(Checklist!B4:B101,B21,Checklist!E4:E101,"OK") | E21: =COUNTIFS(Checklist!B4:B101,B21,Checklist!E4:E101,"KO") | F21: =COUNTIFS(Checklist!B4:B101,B21,Checklist!E4:E101,"Non testé")
B22: 13. Acte III — les 3 lieutenants | C22: =COUNTIF(Checklist!B4:B101,B22) | D22: =COUNTIFS(Checklist!B4:B101,B22,Checklist!E4:E101,"OK") | E22: =COUNTIFS(Checklist!B4:B101,B22,Checklist!E4:E101,"KO") | F22: =COUNTIFS(Checklist!B4:B101,B22,Checklist!E4:E101,"Non testé")
B23: 14. Acte IV — 3 Championnes ralliées | C23: =COUNTIF(Checklist!B4:B101,B23) | D23: =COUNTIFS(Checklist!B4:B101,B23,Checklist!E4:E101,"OK") | E23: =COUNTIFS(Checklist!B4:B101,B23,Checklist!E4:E101,"KO") | F23: =COUNTIFS(Checklist!B4:B101,B23,Checklist!E4:E101,"Non testé")
B24: 15. 7e Arène : retrouvailles avec Blaine (Seafoam) | C24: =COUNTIF(Checklist!B4:B101,B24) | D24: =COUNTIFS(Checklist!B4:B101,B24,Checklist!E4:E101,"OK") | E24: =COUNTIFS(Checklist!B4:B101,B24,Checklist!E4:E101,"KO") | F24: =COUNTIFS(Checklist!B4:B101,B24,Checklist!E4:E101,"Non testé")
B25: 16. Fin du scénario — Kess, Mira Voss, Blue, épilogue | C25: =COUNTIF(Checklist!B4:B101,B25) | D25: =COUNTIFS(Checklist!B4:B101,B25,Checklist!E4:E101,"OK") | E25: =COUNTIFS(Checklist!B4:B101,B25,Checklist!E4:E101,"KO") | F25: =COUNTIFS(Checklist!B4:B101,B25,Checklist!E4:E101,"Non testé")
B26: 17. Les 8 aspirants Champions (rencontres aléatoires) | C26: =COUNTIF(Checklist!B4:B101,B26) | D26: =COUNTIFS(Checklist!B4:B101,B26,Checklist!E4:E101,"OK") | E26: =COUNTIFS(Checklist!B4:B101,B26,Checklist!E4:E101,"KO") | F26: =COUNTIFS(Checklist!B4:B101,B26,Checklist!E4:E101,"Non testé")
B27: 18. Les 18 événements narratifs supplémentaires | C27: =COUNTIF(Checklist!B4:B101,B27) | D27: =COUNTIFS(Checklist!B4:B101,B27,Checklist!E4:E101,"OK") | E27: =COUNTIFS(Checklist!B4:B101,B27,Checklist!E4:E101,"KO") | F27: =COUNTIFS(Checklist!B4:B101,B27,Checklist!E4:E101,"Non testé")
B28: 19. Les 3 histoires secondaires restantes (section 8) | C28: =COUNTIF(Checklist!B4:B101,B28) | D28: =COUNTIFS(Checklist!B4:B101,B28,Checklist!E4:E101,"OK") | E28: =COUNTIFS(Checklist!B4:B101,B28,Checklist!E4:E101,"KO") | F28: =COUNTIFS(Checklist!B4:B101,B28,Checklist!E4:E101,"Non testé")

Sheet Checklist
A1: Heart & Soul — Checklist de test détaillée
A2: Une ligne = un point à vérifier sur une partie neuve. Choisir un statut dans la liste déroulante (colonne Statut) et noter ce qui a été observé en cas de KO.
A3: N° | B3: Section | C3: Élément à vérifier | D3: Zone concernée | E3: Statut | F3: Notes / observations
A4: 1 | B4: 1. Lancement / création de personnage | C4: Écran-titre → Nouvelle Partie → l'écran de choix du genre s'affiche directement, sans discours du Professeur Chen. | E4: Non testé
A5: 2 | B5: 1. Lancement / création de personnage | C5: Choix du genre, saisie du nom : fonctionnent normalement. | D5: Choix du genre, saisie du nom | E5: Non testé
A6: 3 | B6: 1. Lancement / création de personnage | C6: Le jeu démarre au Centre Pokémon de Cinnabar (pas à New Bark Town). | E6: Non testé
A7: 4 | B7: 2. Choix du type et de l'équipe | C7: Le menu des 18 types s'affiche (liste déroulante). | E7: Non testé
A8: 5 | B8: 2. Choix du type et de l'équipe | C8: Choisir un type différent de la dernière fois si possible, pour couvrir les 18 au fil des tests. | E8: Non testé
A9: 6 | B9: 2. Choix du type et de l'équipe | C9: Sélection de 4 Pokémon distincts : un doublon fait bien rouvrir la liste. | D9: Sélection de 4 Pokémon distincts | E9: Non testé
A10: 7 | B10: 2. Choix du type et de l'équipe | C10: Pour au moins un des 4, choix des 4 attaques via le Tuteur de Capacités (bouton B pour arrêter). | E10: Non testé
A11: 8 | B11: 2. Choix du type et de l'équipe | C11: Sac : 5 Poké Balls présentes, + les 8 CT de capacités de terrain (Coupe, Vol, Surf, Force, Flash, Rock Smash, Cascade, Tourbillon), + les 3 cannes à pêche (Old/Good/Super Rod). | D11: Sac | E11: Non testé
A12: 9 | B12: 2. Choix du type et de l'équipe | C12: Sac : la Bicyclette est présente et utilisable. | D12: Sac | E12: Non testé
A13: 10 | B13: 2. Choix du type et de l'équipe | C13: Menu START : entrée « Pokémon » présente (équipe consultable). | D13: Menu START | E13: Non testé
A14: 11 | B14: 2. Choix du type et de l'équipe | C14: Menu START : entrée « Pokénav »/Pokégear présente (carte accessible). | D14: Menu START | E14: Non testé
A15: 12 | B15: 2. Choix du type et de l'équipe | C15: Chaussures de course actives (bouton B pour courir sur la carte). | E15: Non testé
A16: 13 | B16: 3. Attaque de Cinnabar (Acte I) | C16: Narration de l'attaque, un Grunt fait irruption, Blaine s'interpose puis disparaît (texte uniquement, pas de sprite visible à ce moment). | E16: Non testé
A17: 14 | B17: 3. Attaque de Cinnabar (Acte I) | C17: Un second Grunt bloque le passage juste après : combat forcé (pas de choix, pas de fuite possible), équipe niveau ~34. Après la victoire, le texte confirme que le passage vers le Mont Cinnabar est libre. | D17: Un second Grunt bloque le passage juste après | E17: Non testé
A18: 15 | B18: 3. Attaque de Cinnabar (Acte I) | C18: Choix réfugiés (guider / cacher) : les deux options fonctionnent, message de résultat cohérent. | D18: Choix réfugiés | E18: Non testé
A19: 16 | B19: 3. Attaque de Cinnabar (Acte I) | C19: Message de fuite → fondu au noir → téléportation automatique à Pallet Town, sans avoir à marcher ni utiliser un CS Fly. | E19: Non testé
A20: 17 | B20: 3. Attaque de Cinnabar (Acte I) | C20: Essayer de retourner vers Cinnabar (Route 21, vers le sud) : le jeu doit repousser le joueur avec un message, pas de possibilité d'entrer. | D20: Essayer de retourner vers Cinnabar | E20: Non testé
A21: 18 | B21: 4. Route 1 | C21: Combattre Quinn (Cooltrainer F). | E21: Non testé
A22: 19 | B22: 4. Route 1 | C22: Juste après la victoire, sans avoir à lui reparler : dialogue de post-combat puis proposition de rendre le bracelet trouvé à Cinnabar. | D22: Juste après la victoire, sans avoir à lui reparler | E22: Non testé
A23: 20 | B23: 4. Route 1 | C23: Tester les deux choix (rendre / garder) sur des essais différents si possible. | E23: Non testé
A24: 21 | B24: 5. Viridian (Argenta) | C24: Mart : parler au PNJ (ex-« Cooltrainer M ») → proposition de rejoindre la résistance, choix aider/décliner fonctionnent. | D24: Mart | E24: Non testé
A25: 22 | B25: 5. Viridian (Argenta) | C25: Mart : parler au vendeur (comptoir) → un vrai magasin s'ouvre avec Poké Ball/Potion/Antidote/Anti-Paralysie à acheter. | D25: Mart | E25: Non testé
A26: 23 | B26: 5. Viridian (Argenta) | C26: Arène : Blue est absent, le PNJ à l'intérieur explique que l'Arène est fermée (pas de combat possible). | D26: Arène | E26: Non testé
A27: 24 | B27: 6. Forêt de Jade (Viridian Forest) | C27: Combattre Doug (Bug Catcher) — il erre assez loin de l'entrée nord, plutôt vers le centre-sud de la forêt, proche de la sortie côté Jadielle/Pewter. Continuer vers le sud si non trouvé près de l'entrée. | E27: Non testé
A28: 25 | B28: 6. Forêt de Jade (Viridian Forest) | C28: Juste après la victoire, sans avoir à lui reparler : dialogue bûcherons déplacés, choix aider/ignorer fonctionnent. | D28: Juste après la victoire, sans avoir à lui reparler | E28: Non testé
A29: 26 | B29: 7. Argenta → Jadielle → Azuria (route et niveaux) | C29: Pokémon sauvages rencontrés sur Route 1/2/3/4, Forêt de Jade, Mont Sélénite : niveau ~34 (pas 45+). | E29: Non testé
A30: 27 | B30: 7. Argenta → Jadielle → Azuria (route et niveaux) | C30: Dresseurs rencontrés sur la route (Danny, Ed, Rob, etc.) : niveau ~34. | D30: Dresseurs rencontrés sur la route | E30: Non testé
A31: 28 | B31: 7. Argenta → Jadielle → Azuria (route et niveaux) | C31: Coupe/Surf/Vol/Force/etc. utilisable sans badge depuis le menu Pokémon (CT + Pokémon compatible fournis dès le départ, voir section 2). | E31: Non testé
A32: 29 | B32: 8. Arène de Pierre (Jadielle) | C32: Mart de Jadielle : le vendeur au comptoir vend Poké Ball/Potion/Antidote/Anti-Paralysie/Réveil/Anti-Brûlure/Corde Sortie/Repousse. | D32: Mart de Jadielle | E32: Non testé
A33: 30 | B33: 8. Arène de Pierre (Jadielle) | C33: En arrivant à l'Arène : seul notre dialogue (Pierre doute) s'affiche, puis le combat démarre directement — plus de texte anglais générique avant le combat. | D33: En arrivant à l'Arène | E33: Non testé
A34: 31 | B34: 8. Arène de Pierre (Jadielle) | C34: Perdre volontairement ce premier combat, puis reparler à Pierre : la scène de doute (en français) doit se rejouer. | E34: Non testé
A35: 32 | B35: 8. Arène de Pierre (Jadielle) | C35: Gagner le combat : badge + CT Éboulement reçus normalement, puis un nouveau texte (en français, lié à notre histoire) où Pierre reconnaît avoir été convaincu. | D35: Gagner le combat | E35: Non testé
A36: 33 | B36: 9. Azuria | C36: Mart d'Azuria : le vendeur vend en plus une Super Potion. | D36: Mart d'Azuria | E36: Non testé
A37: 34 | B37: 9. Azuria | C37: Avant de réparer les canalisations : à l'Arène, Ondine explique le problème (Arène inondée/bloquée) et dit qu'elle n'écoutera qu'une fois les canalisations réparées — pas de combat possible à ce stade. | D37: Avant de réparer les canalisations | E37: Non testé
A38: 35 | B38: 9. Azuria | C38: Toujours avant réparation : un PNJ Team Rocket est présent et interactif dans l'Arène (parler à lui affiche une ligne de sabotage). | D38: Toujours avant réparation | E38: Non testé
A39: 36 | B39: 9. Azuria | C39: PNJ « canalisations sabotées » (Boy, en ville) : choix aider/ignorer fonctionnent, réparation obtenue. | D39: PNJ « canalisations sabotées » | E39: Non testé
A40: 37 | B40: 9. Azuria | C40: Après réparation des canalisations : retourner à l'Arène — le PNJ Rocket a disparu, le combat contre Ondine est maintenant possible (notre dialogue, puis le combat) ; en cas de défaite, la scène se rejoue à la tentative suivante. | D40: Après réparation des canalisations | E40: Non testé
...
